Workbook

Sheet Work Flow
H3: Overall program flow diagram

Sheet INPUT SHEET
A1: S NO | B1: DESCRIPTION | C1: UoM | D1: DESIGN_VALUE | E1: OPERATING_VALUE | G1: S NO | H1: DESCRIPTION | I1: UoM | J1: DESIGN_VALUE | K1: OPTIMAL LIMIT | L1: OPERATING_VALUE
B2: BASIC PROCESS PARAMETERS | G2: ELECTRICAL PARAMETERS | L2: Mill-A | M2: Mill-B | N2: Mill-C | O2: Mill-D | P2: Mill-E | Q2: Mill-F | S2: Mill-A | T2: Mill-B | U2: Mill-C | V2: Mill-D | W2: Mill-E | X2: Mill-F | AA2: AVAILABLE
A3: 1 | B3: NUMBER OF FD FANS IN SERVICE | C3: Nos. | D3: 2 | E3: 2 | G3: 38 | H3: MOTOR CURRENT | I3: A | J3: 35 | K3: =ROUND(J3*0.95,0) -> 33 | L3: 27 | M3: 29 | N3: 27 | O3: 31 | P3: 33 | Q3: 0 | AA3: NOT AVAILABLE
A4: 2 | B4: NUMBER OF ID FANS IN SERVICE | C4: Nos. | D4: 2 | E4: 2 | G4: 39 | H4: ELECTRICAL VOLTAGE | I4: Volts | J4: 3300 | K4: =J4 -> 3300 | L4: 3300 | M4: 3300 | N4: 3300 | O4: 3300 | P4: 3300 | Q4: 3300 | AA4: STANDBY
A5: 3 | B5: NUMBER OF PA FANS IN SERVICE | C5: Nos. | D5: 2 | E5: 2 | G5: 40 | H5: INSULATION RESISTANCE | I5: Ω | J5: 1000 | K5: =J5 -> 1000 | L5: 1100 | M5: 1100 | N5: 1100 | O5: 1100 | P5: 1100 | Q5: 1100 | S5: =IF(L5>$K5,1,0) -> 1 | T5: =IF(M5>$K5,1,0) -> 1 | U5: =IF(N5>$K5,1,0) -> 1 | V5: =IF(O5>$K5,1,0) -> 1 | W5: =IF(P5>$K5,1,0) -> 1 | X5: =IF(Q5>$K5,1,0) -> 1
A6: 4 | B6: NUMBER OF APHs IN SERVICE | C6: Nos. | D6: 2 | E6: 2 | G6: 41 | H6: MOTOR WINDING TEMPERATURE | I6: ˚C | J6: 95 | K6: =(ROUND(J6*0.95,0)) -> 90 | L6: 88 | M6: 88 | N6: 88 | O6: 88 | P6: 88 | Q6: 88 | S6: =IF(L6<0.9*$K6,1,IF(L6<=0.98*$K6,0.5,IF(L6>0.98*$K6,0))) -> 0.5 | T6: =IF(M6<0.9*$K6,1,IF(M6<=0.98*$K6,0.5,IF(M6>0.98*$K6,0))) -> 0.5 | U6: =IF(N6<0.9*$K6,1,IF(N6<=0.98*$K6,0.5,IF(N6>0.98*$K6,0))) -> 0.5 | V6: =IF(O6<0.9*$K6,1,IF(O6<=0.98*$K6,0.5,IF(O6>0.98*$K6,0))) -> 0.5 | W6: =IF(P6<0.9*$K6,1,IF(P6<=0.98*$K6,0.5,IF(P6>0.98*$K6,0))) -> 0.5 | X6: =IF(Q6<0.9*$K6,1,IF(Q6<=0.98*$K6,0.5,IF(Q6>0.98*$K6,0))) -> 0.5
A7: 5 | B7: NUMBER OF SEAL AIR FANS IN SERVICE | C7: Nos. | D7: 1 | E7: 1 | G7: 42 | H7: POLARISATION INDEX | I7: - | J7: 3 | K7: =0.9*J7 -> 2.7 | L7: 2.8 | M7: 2.8 | N7: 2.8 | O7: 2.8 | P7: 2.8 | Q7: 2.8 | S7: =IF(L7>$K7,1,0) -> 1 | T7: =IF(M7>$K7,1,0) -> 1 | U7: =IF(N7>$K7,1,0) -> 1 | V7: =IF(O7>$K7,1,0) -> 1 | W7: =IF(P7>$K7,1,0) -> 1 | X7: =IF(Q7>$K7,1,0) -> 1
A8: 6 | B8: LOAD | C8: MW | D8: ='[1]Basic Inputs'!D4 -> 300 | E8: ='[1]Basic Inputs'!E4 -> 299.95 | G8: 43 | H8: TEN DELTA | J8: 0.01 | K8: =J8 -> 0.01 | L8: 0.008 | M8: 0.008 | N8: 0.008 | O8: 0.008 | P8: 0.008 | Q8: 0.008 | S8: =IF(L8<$K$8,1,0) -> 1 | T8: =IF(M8<$K$8,1,0) -> 1 | U8: =IF(N8<$K$8,1,0) -> 1 | V8: =IF(O8<$K$8,1,0) -> 1 | W8: =IF(P8<$K$8,1,0) -> 1 | X8: =IF(Q8<$K$8,1,0) -> 1
A9: 7 | B9: MAIN STEAM FLOW | C9: TPH | D9: 900 | E9: 900 | G9: 44 | H9: MOTOR BEARING VIBRATION | I9: m/sec | J9: 1.5 | K9: =J9*0.8 -> 1.2 | L9: 1 | M9: 1 | N9: 1.1 | O9: 1 | P9: 1 | Q9: 1 | S9: =IF(L9<0.9*$K9,1,IF(L9<=0.98*$K9,0.5,IF(L9>0.98*$K9,0))) -> 1 | T9: =IF(M9<0.9*$K9,1,IF(M9<=0.98*$K9,0.5,IF(M9>0.98*$K9,0))) -> 1 | U9: =IF(N9<0.9*$K9,1,IF(N9<=0.98*$K9,0.5,IF(N9>0.98*$K9,0))) -> 0.5 | V9: =IF(O9<0.9*$K9,1,IF(O9<=0.98*$K9,0.5,IF(O9>0.98*$K9,0))) -> 1 | W9: =IF(P9<0.9*$K9,1,IF(P9<=0.98*$K9,0.5,IF(P9>0.98*$K9,0))) -> 1 | X9: =IF(Q9<0.9*$K9,1,IF(Q9<=0.98*$K9,0.5,IF(Q9>0.98*$K9,0))) -> 1
A10: 8 | B10: TOTAL AIR FLOW | C10: TPH | D10: 1000 | E10: 1000 | G10: 45 | H10: MOTOR BEARING TEMPERATURE | I10: ˚C | J10: 75 | K10: =(ROUND(J10*0.95,0)) -> 71 | L10: 200 | M10: 65 | N10: 57 | O10: 65 | P10: 64 | Q10: 65 | S10: =IF(L10<0.9*$K10,1,IF(L10<=0.98*$K10,0.5,IF(L10>0.98*$K10,0))) -> 0 | T10: =IF(M10<0.9*$K10,1,IF(M10<=0.98*$K10,0.5,IF(M10>0.98*$K10,0))) -> 0.5 | U10: =IF(N10<0.9*$K10,1,IF(N10<=0.98*$K10,0.5,IF(N10>0.98*$K10,0))) -> 1 | V10: =IF(O10<0.9*$K10,1,IF(O10<=0.98*$K10,0.5,IF(O10>0.98*$K10,0))) -> 0.5 | W10: =IF(P10<0.9*$K10,1,IF(P10<=0.98*$K10,0.5,IF(P10>0.98*$K10,0))) -> 0.5 | X10: =IF(Q10<0.9*$K10,1,IF(Q10<=0.98*$K10,0.5,IF(Q10>0.98*$K10,0))) -> 0.5
A11: 9 | B11: TOTAL SECONDARY AIR FLOW | C11: TPH | D11: 800 | E11: 800 | G11: 46 | H11: MILL POWER CONSUMPTION | J11: =1.732*J4*J3*0.85/1000 -> 170.0391 | K11: =(ROUND(J11*0.98,0)) -> 167 | L11: =1.732*L4*L3*0.85/1000 -> 131.17302 | M11: =1.732*M4*M3*0.85/1000 -> 140.88954 | N11: =1.732*N4*N3*0.85/1000 -> 131.17302 | O11: =1.732*O4*O3*0.85/1000 -> 150.60606 | P11: =1.732*P4*P3*0.85/1000 -> 160.32258 | Q11: =1.732*Q4*Q3*0.85/1000 -> 0 | S11: =IF(L11<0.95*$K11,1,IF(L11<=1*$K11,0.5,IF(L11>1*$K11,0))) -> 1 | T11: =IF(M11<0.95*$K11,1,IF(M11<=1*$K11,0.5,IF(M11>1*$K11,0))) -> 1 | U11: =IF(N11<0.95*$K11,1,IF(N11<=1*$K11,0.5,IF(N11>1*$K11,0))) -> 1 | V11: =IF(O11<0.95*$K11,1,IF(O11<=1*$K11,0.5,IF(O11>1*$K11,0))) -> 1 | W11: =IF(P11<0.95*$K11,1,IF(P11<=1*$K11,0.5,IF(P11>1*$K11,0))) -> 0.5 | X11: =IF(Q11<0.95*$K11,1,IF(Q11<=1*$K11,0.5,IF(Q11>1*$K11,0))) -> 1
A12: 10 | B12: TOTAL COAL FLOW | C12: TPH | D12: 103.9 | E12: 115.3 | G12: MECHANICAL PARAMETERS
A13: 11 | B13: AMBIENT PRESSURE | C13: bar (a) | D13: 1.013 | E13: 1.013 | G13: 47 | H13: MILL BEARING VIBRATION | I13: m/sec | J13: 1.5 | K13: =J13*0.8 -> 1.2 | L13: 1.1 | M13: 1 | N13: 1 | O13: 1 | P13: 1 | Q13: 1 | S13: =IF(L13<0.9*$K13,1,IF(L13<=0.98*$K13,0.5,IF(L13>0.98*$K13,0))) -> 0.5 | T13: =IF(M13<0.9*$K13,1,IF(M13<=0.98*$K13,0.5,IF(M13>0.98*$K13,0))) -> 1 | U13: =IF(N13<0.9*$K13,1,IF(N13<=0.98*$K13,0.5,IF(N13>0.98*$K13,0))) -> 1 | V13: =IF(O13<0.9*$K13,1,IF(O13<=0.98*$K13,0.5,IF(O13>0.98*$K13,0))) -> 1 | W13: =IF(P13<0.9*$K13,1,IF(P13<=0.98*$K13,0.5,IF(P13>0.98*$K13,0))) -> 1 | X13: =IF(Q13<0.9*$K13,1,IF(Q13<=0.98*$K13,0.5,IF(Q13>0.98*$K13,0))) -> 1
A14: 12 | B14: AMBIENT TEMPERATURE | C14: °C | D14: 35 | E14: 35 | G14: 48 | H14: MILL BEARING TEMPERATURE | I14: ˚C | J14: 75 | K14: =(ROUND(J14*0.95,0)) -> 71 | L14: 62 | M14: 65 | N14: 65 | O14: 65 | P14: 65 | Q14: 65 | S14: =IF(L14<0.9*$K14,1,IF(L14<=0.98*$K14,0.5,IF(L14>0.98*$K14,0))) -> 1 | T14: =IF(M14<0.9*$K14,1,IF(M14<=0.98*$K14,0.5,IF(M14>0.98*$K14,0))) -> 0.5 | U14: =IF(N14<0.9*$K14,1,IF(N14<=0.98*$K14,0.5,IF(N14>0.98*$K14,0))) -> 0.5 | V14: =IF(O14<0.9*$K14,1,IF(O14<=0.98*$K14,0.5,IF(O14>0.98*$K14,0))) -> 0.5 | W14: =IF(P14<0.9*$K14,1,IF(P14<=0.98*$K14,0.5,IF(P14>0.98*$K14,0))) -> 0.5 | X14: =IF(Q14<0.9*$K14,1,IF(Q14<=0.98*$K14,0.5,IF(Q14>0.98*$K14,0))) -> 0.5
A15: 13 | B15: RELATIVE HUMIDITY | C15: % | D15: 50 | E15: 50 | G15: 49 | H15: MILL/FEEDER ABNORMAL TRIP IN LAST QUARTER | J15: 0 | K15: 1 | L15: 0 | M15: 0 | N15: 0 | O15: 0 | P15: 0 | Q15: 0 | S15: =IF(L15<$K15,1,IF(L15<=2*$K15,0.5,IF(L15>2*$K15,0))) -> 1 | T15: =IF(M15<$K15,1,IF(M15<=2*$K15,0.5,IF(M15>2*$K15,0))) -> 1 | U15: =IF(N15<$K15,1,IF(N15<=2*$K15,0.5,IF(N15>2*$K15,0))) -> 1 | V15: =IF(O15<$K15,1,IF(O15<=2*$K15,0.5,IF(O15>2*$K15,0))) -> 1 | W15: =IF(P15<$K15,1,IF(P15<=2*$K15,0.5,IF(P15>2*$K15,0))) -> 1 | X15: =IF(Q15<$K15,1,IF(Q15<=2*$K15,0.5,IF(Q15>2*$K15,0))) -> 1
A16: 14 | B16: NO. OF MILLS IN SERVICE | C16: - | D16: 6 | E16: =COUNTIF(D38:D43,"AVAILABLE") -> 6 | G16: 50 | H16: RUNNING HOURS SINCE LAST MAINTENANCE | I16: Hrs | J16: =8760/2 -> 4380 | K16: =J16*0.8 -> 3504 | L16: 8000 | M16: 2200 | N16: 1500 | O16: 2300 | P16: 2250 | Q16: 1500 | S16: =IF(L16<$K16,1,IF(L16<=2*$K16,0.5,IF(L16>2*$K16,0))) -> 0 | T16: =IF(M16<$K16,1,IF(M16<=2*$K16,0.5,IF(M16>2*$K16,0))) -> 1 | U16: =IF(N16<$K16,1,IF(N16<=2*$K16,0.5,IF(N16>2*$K16,0))) -> 1 | V16: =IF(O16<$K16,1,IF(O16<=2*$K16,0.5,IF(O16>2*$K16,0))) -> 1 | W16: =IF(P16<$K16,1,IF(P16<=2*$K16,0.5,IF(P16>2*$K16,0))) -> 1 | X16: =IF(Q16<$K16,1,IF(Q16<=2*$K16,0.5,IF(Q16>2*$K16,0))) -> 1
A17: 15 | B17: ALLOWABLE COAL FLOW PER MILL | C17: TPH | D17: 28 | E17: 28 | G17: OPERATIONAL PARAMETERS
A18: 16 | B18: MS PRESSURE | C18: MPa | D18: 16.67 | E18: 16 | G18: 51 | H18: FEEDER COAL FLOW | I18: TPH | J18: 30 | K18: =(ROUND(J18*0.95,0)) -> 29 | L18: 22 | M18: 24.8 | N18: 24 | O18: 23.7 | P18: 20.8 | Q18: 0 | S18: =IF(L18<0.9*$K18,1,IF(L18<=0.98*$K18,0.5,IF(L18>0.98*$K18,0))) -> 1 | T18: =IF(M18<0.9*$K18,1,IF(M18<=0.98*$K18,0.5,IF(M18>0.98*$K18,0))) -> 1 | U18: =IF(N18<0.9*$K18,1,IF(N18<=0.98*$K18,0.5,IF(N18>0.98*$K18,0))) -> 1 | V18: =IF(O18<0.9*$K18,1,IF(O18<=0.98*$K18,0.5,IF(O18>0.98*$K18,0))) -> 1 | W18: =IF(P18<0.9*$K18,1,IF(P18<=0.98*$K18,0.5,IF(P18>0.98*$K18,0))) -> 1 | X18: =IF(Q18<0.9*$K18,1,IF(Q18<=0.98*$K18,0.5,IF(Q18>0.98*$K18,0))) -> 1
A19: 17 | B19: MS TEMPERATURE | C19: ˚C | D19: 538 | E19: 530 | G19: 52 | H19: PA FLOW | I19: TPH | J19: 60 | K19: =ROUND(J19*1,0) -> 60 | L19: 65 | M19: 65 | N19: 65 | O19: 65 | P19: 65 | Q19: 65 | S19: =IF(L19<0.6*$K19,0,IF(L19<=0.98*$K19,0.5,IF(L19>0.98*$K19,1))) -> 1 | T19: =IF(M19<0.6*$K19,0,IF(M19<=0.98*$K19,0.5,IF(M19>0.98*$K19,1))) -> 1 | U19: =IF(N19<0.6*$K19,0,IF(N19<=0.98*$K19,0.5,IF(N19>0.98*$K19,1))) -> 1 | V19: =IF(O19<0.6*$K19,0,IF(O19<=0.98*$K19,0.5,IF(O19>0.98*$K19,1))) -> 1 | W19: =IF(P19<0.6*$K19,0,IF(P19<=0.98*$K19,0.5,IF(P19>0.98*$K19,1))) -> 1 | X19: =IF(Q19<0.6*$K19,0,IF(Q19<=0.98*$K19,0.5,IF(Q19>0.98*$K19,1))) -> 1
A20: 18 | B20: HRH TEMPERATURE | C20: ˚C | D20: 538 | E20: 535 | G20: 53 | H20: INLET TEMPERATURE | I20: ˚C | J20: 170 | K20: =(ROUND(J20*0.95,0)) -> 162 | L20: 175 | M20: 175 | N20: 175 | O20: 175 | P20: 175 | Q20: 175 | S20: =IF(L20<0.9*$K20,1,IF(L20<=0.98*$K20,0.5,IF(L20>0.98*$K20,0))) -> 0 | T20: =IF(M20<0.9*$K20,1,IF(M20<=0.98*$K20,0.5,IF(M20>0.98*$K20,0))) -> 0 | U20: =IF(N20<0.9*$K20,1,IF(N20<=0.98*$K20,0.5,IF(N20>0.98*$K20,0))) -> 0 | V20: =IF(O20<0.9*$K20,1,IF(O20<=0.98*$K20,0.5,IF(O20>0.98*$K20,0))) -> 0 | W20: =IF(P20<0.9*$K20,1,IF(P20<=0.98*$K20,0.5,IF(P20>0.98*$K20,0))) -> 0 | X20: =IF(Q20<0.9*$K20,1,IF(Q20<=0.98*$K20,0.5,IF(Q20>0.98*$K20,0))) -> 0
A21: 19 | B21: SUPER HEATER SPRAY | C21: TPH | D21: 26.2 | E21: 35 | G21: 54 | H21: BOWL DP | I21: Pa | J21: 200 | K21: =(ROUND(J21*0.95,0)) -> 190 | L21: 180 | M21: 180 | N21: 180 | O21: 180 | P21: 180 | Q21: 60 | S21: =IF(L21<0.9*$K21,1,IF(L21<=0.98*$K21,0.5,IF(L21>0.98*$K21,0))) -> 0.5 | T21: =IF(M21<0.9*$K21,1,IF(M21<=0.98*$K21,0.5,IF(M21>0.98*$K21,0))) -> 0.5 | U21: =IF(N21<0.9*$K21,1,IF(N21<=0.98*$K21,0.5,IF(N21>0.98*$K21,0))) -> 0.5 | V21: =IF(O21<0.9*$K21,1,IF(O21<=0.98*$K21,0.5,IF(O21>0.98*$K21,0))) -> 0.5 | W21: =IF(P21<0.9*$K21,1,IF(P21<=0.98*$K21,0.5,IF(P21>0.98*$K21,0))) -> 0.5 | X21: =IF(Q21<0.9*$K21,1,IF(Q21<=0.98*$K21,0.5,IF(Q21>0.98*$K21,0))) -> 1
A22: 20 | B22: REHEATER SPRAY | C22: TPH | D22: 0 | E22: 25 | G22: 55 | H22: OUTLET TEMPERATURE | I22: ˚C | J22: 75 | K22: 71 | L22: 67 | M22: 62 | N22: 65 | O22: 67 | P22: 65 | Q22: 0 | S22: =IF(L22<0.9*$K22,1,IF(L22<=0.98*$K22,0.5,IF(L22>0.98*$K22,0))) -> 0.5 | T22: =IF(M22<0.9*$K22,1,IF(M22<=0.98*$K22,0.5,IF(M22>0.98*$K22,0))) -> 1 | U22: =IF(N22<0.9*$K22,1,IF(N22<=0.98*$K22,0.5,IF(N22>0.98*$K22,0))) -> 0.5 | V22: =IF(O22<0.9*$K22,1,IF(O22<=0.98*$K22,0.5,IF(O22>0.98*$K22,0))) -> 0.5 | W22: =IF(P22<0.9*$K22,1,IF(P22<=0.98*$K22,0.5,IF(P22>0.98*$K22,0))) -> 0.5 | X22: =IF(Q22<0.9*$K22,1,IF(Q22<=0.98*$K22,0.5,IF(Q22>0.98*$K22,0))) -> 1
A23: 21 | B23: HIGHEST METAL TEMPERATURE | C23: ˚C | D23: 570 | E23: 585 | G23: 56 | H23: PA INLET PRESSURE | I23: mmWC | J23: 160 | K23: =(ROUND(J23*0.95,0)) -> 152 | L23: 200 | M23: 200 | N23: 200 | O23: 200 | P23: 200 | Q23: 20 | S23: =IF(L23<0.8*$K23,0,IF(L23<=0.9*$K23,0.5,IF(L23>0.9*$K23,1))) -> 1 | T23: =IF(M23<0.8*$K23,0,IF(M23<=0.9*$K23,0.5,IF(M23>0.9*$K23,1))) -> 1 | U23: =IF(N23<0.8*$K23,0,IF(N23<=0.9*$K23,0.5,IF(N23>0.9*$K23,1))) -> 1 | V23: =IF(O23<0.8*$K23,0,IF(O23<=0.9*$K23,0.5,IF(O23>0.9*$K23,1))) -> 1 | W23: =IF(P23<0.8*$K23,0,IF(P23<=0.9*$K23,0.5,IF(P23>0.9*$K23,1))) -> 1 | X23: =IF(Q23<0.8*$K23,0,IF(Q23<=0.9*$K23,0.5,IF(Q23>0.9*$K23,1))) -> 0
A24: 22 | B24: APH INLET FLUE GAS TEMPERATURE | C24: ˚C | D24: 339.11 | E24: 345 | G24: 57 | H24: MILL TO SEAL AIR DP | I24: Pa | J24: 2000 | K24: =(ROUND(J24*0.95,0)) -> 1900 | L24: 1500 | M24: 1500 | N24: 1500 | O24: 1500 | P24: 1500 | Q24: 20 | S24: =IF(L24<0.9*$K24,1,IF(L24<=0.98*$K24,0.5,IF(L24>0.98*$K24,0))) -> 1 | T24: =IF(M24<0.9*$K24,1,IF(M24<=0.98*$K24,0.5,IF(M24>0.98*$K24,0))) -> 1 | U24: =IF(N24<0.9*$K24,1,IF(N24<=0.98*$K24,0.5,IF(N24>0.98*$K24,0))) -> 1 | V24: =IF(O24<0.9*$K24,1,IF(O24<=0.98*$K24,0.5,IF(O24>0.98*$K24,0))) -> 1 | W24: =IF(P24<0.9*$K24,1,IF(P24<=0.98*$K24,0.5,IF(P24>0.98*$K24,0))) -> 1 | X24: =IF(Q24<0.9*$K24,1,IF(Q24<=0.98*$K24,0.5,IF(Q24>0.98*$K24,0))) -> 1
A25: 23 | B25: APH INLET FLUE GAS OXYGEN | C25: % | D25: 3.5 | E25: 3.8 | G25: 58 | H25: MILL FINENESS | I25: - | J25: HEALTHY | K25: =J25 -> HEALTHY | L25: HEALTHY | M25: HEALTHY | N25: HEALTHY | O25: HEALTHY | P25: HEALTHY | Q25: HEALTHY | S25: =IF(L25 = "HEALTHY",1,0) -> 1 | T25: =IF(M25 = "HEALTHY",1,0) -> 1 | U25: =IF(N25 = "HEALTHY",1,0) -> 1 | V25: =IF(O25 = "HEALTHY",1,0) -> 1 | W25: =IF(P25 = "HEALTHY",1,0) -> 1 | X25: =IF(Q25 = "HEALTHY",1,0) -> 1
A26: 24 | B26: PLANT GROSS HEAT RATE | C26: kCal/kWh | D26: =1920/0.88 -> 2181.8182 | E26: 2372 | G26: 59 | H26: COAL PIPE TEMPERATURE | I26: ˚C | J26: 65 | K26: =(ROUND(J26*0.95,0)) -> 62 | L26: 57 | M26: 55 | N26: 58 | O26: 57 | P26: 58 | Q26: 27 | S26: =IF(L26<0.9*$K26,1,IF(L26<=0.98*$K26,0.5,IF(L26>0.98*$K26,0))) -> 0.5 | T26: =IF(M26<0.9*$K26,1,IF(M26<=0.98*$K26,0.5,IF(M26>0.98*$K26,0))) -> 1 | U26: =IF(N26<0.9*$K26,1,IF(N26<=0.98*$K26,0.5,IF(N26>0.98*$K26,0))) -> 0.5 | V26: =IF(O26<0.9*$K26,1,IF(O26<=0.98*$K26,0.5,IF(O26>0.98*$K26,0))) -> 0.5 | W26: =IF(P26<0.9*$K26,1,IF(P26<=0.98*$K26,0.5,IF(P26>0.98*$K26,0))) -> 0.5 | X26: =IF(Q26<0.9*$K26,1,IF(Q26<=0.98*$K26,0.5,IF(Q26>0.98*$K26,0))) -> 1
B27: COAL AND ASH DETAILS | G27: 60 | H27: LUBE OIL PRESSURE | I27: Mpa | J27: 0.25 | K27: =J27 -> 0.25 | L27: 0.3 | M27: 0.18 | N27: 0.3 | O27: 0.3 | P27: 0.3 | Q27: 0.3 | S27: =IF(L27<0.9*$K27,0,IF(L27<=0.98*$K27,0.5,IF(L27>0.98*$K27,1))) -> 1 | T27: =IF(M27<0.9*$K27,0,IF(M27<=0.98*$K27,0.5,IF(M27>0.98*$K27,1))) -> 0 | U27: =IF(N27<0.9*$K27,0,IF(N27<=0.98*$K27,0.5,IF(N27>0.98*$K27,1))) -> 1 | V27: =IF(O27<0.9*$K27,0,IF(O27<=0.98*$K27,0.5,IF(O27>0.98*$K27,1))) -> 1 | W27: =IF(P27<0.9*$K27,0,IF(P27<=0.98*$K27,0.5,IF(P27>0.98*$K27,1))) -> 1 | X27: =IF(Q27<0.9*$K27,0,IF(Q27<=0.98*$K27,0.5,IF(Q27>0.98*$K27,1))) -> 1
B28: COAL PROXIMATE ANALYSIS (AFB) | G28: 61 | H28: MILL REJECT CONDITION | I28: - | J28: HEALTHY | K28: =J28 -> HEALTHY | L28: HEALTHY | M28: HEALTHY | N28: HEALTHY | O28: HEALTHY | P28: HEALTHY | Q28: HEALTHY | S28: =IF(L28 = "HEALTHY",1,0) -> 1 | T28: =IF(M28 = "HEALTHY",1,0) -> 1 | U28: =IF(N28 = "HEALTHY",1,0) -> 1 | V28: =IF(O28 = "HEALTHY",1,0) -> 1 | W28: =IF(P28 = "HEALTHY",1,0) -> 1 | X28: =IF(Q28 = "HEALTHY",1,0) -> 1
A29: 25 | B29: TOTAL MOISTURE CONTENT | C29: % | D29: 11 | E29: 11 | G29: 62 | H29: FLAME INTENSITY HEALTHINESS % | I29: % | J29: HEALTHY | K29: =J29 -> HEALTHY | L29: HEALTHY | M29: HEALTHY | N29: HEALTHY | O29: HEALTHY | P29: HEALTHY | Q29: HEALTHY | S29: =IF(L29 = "HEALTHY",1,0) -> 1 | T29: =IF(M29 = "HEALTHY",1,0) -> 1 | U29: =IF(N29 = "HEALTHY",1,0) -> 1 | V29: =IF(O29 = "HEALTHY",1,0) -> 1 | W29: =IF(P29 = "HEALTHY",1,0) -> 1 | X29: =IF(Q29 = "HEALTHY",1,0) -> 1
A30: 26 | B30: ASH CONTENT | C30: % | D30: 11.12 | E30: 11.12 | G30: 63 | H30: INERT STEAM AVAILABILITY | I30: - | J30: HEALTHY | K30: =J30 -> HEALTHY | L30: HEALTHY | M30: HEALTHY | N30: HEALTHY | O30: HEALTHY | P30: HEALTHY | Q30: HEALTHY | S30: =IF(L30 = "HEALTHY",1,0) -> 1 | T30: =IF(M30 = "HEALTHY",1,0) -> 1 | U30: =IF(N30 = "HEALTHY",1,0) -> 1 | V30: =IF(O30 = "HEALTHY",1,0) -> 1 | W30: =IF(P30 = "HEALTHY",1,0) -> 1 | X30: =IF(Q30 = "HEALTHY",1,0) -> 1
A31: 27 | B31: FIXED CARBON | C31: % | D31: 46.73 | E31: 46.73 | G31: 64 | H31: MILL SPECIFIC POWER CONSUMPTION | I31: kWh/T | J31: =J11/J18 -> 5.66797 | K31: =ROUND(J31*1.05,0) -> 6 | L31: =IF(L11>0,L11/L18,0) -> 5.96241 | M31: =IF(M11>0,M11/M18,0) -> 5.6810298 | N31: =IF(N11>0,N11/N18,0) -> 5.4655425 | O31: =IF(O11>0,O11/O18,0) -> 6.3546861 | P31: =IF(P11>0,P11/P18,0) -> 7.7078163 | Q31: =IF(Q11>0,Q11/Q18,0) -> 0 | S31: =IF(L31<0.95*$K31,1,IF(L31<=1*$K31,0.5,IF(L31>1*$K31,0))) -> 0.5 | T31: =IF(M31<0.95*$K31,1,IF(M31<=1*$K31,0.5,IF(M31>1*$K31,0))) -> 1 | U31: =IF(N31<0.95*$K31,1,IF(N31<=1*$K31,0.5,IF(N31>1*$K31,0))) -> 1 | V31: =IF(O31<0.95*$K31,1,IF(O31<=1*$K31,0.5,IF(O31>1*$K31,0))) -> 0 | W31: =IF(P31<0.95*$K31,1,IF(P31<=1*$K31,0.5,IF(P31>1*$K31,0))) -> 0 | X31: =IF(Q31<0.95*$K31,1,IF(Q31<=1*$K31,0.5,IF(Q31>1*$K31,0))) -> 1
A32: 28 | B32: VOLATILE MATTER | C32: % | D32: 31.15 | E32: 31.15 | G32: 65 | H32: PRIMARY AIR FLOW TO COAL RATIO | I32: - | J32: =J19/J18 -> 2 | K32: =ROUND(J32*1.05,0) -> 2 | L32: =IF(L18>0,L19/L18,0) -> 2.9545455 | M32: =IF(M18>0,M19/M18,0) -> 2.6209677 | N32: =IF(N18>0,N19/N18,0) -> 2.7083333 | O32: =IF(O18>0,O19/O18,0) -> 2.742616 | P32: =IF(P18>0,P19/P18,0) -> 3.125 | Q32: =IF(Q18>0,Q19/Q18,0) -> 0 | S32: =IF(L32<0.8*$K32,0,IF(L32<=0.9*$K32,0.5,IF(L32>0.9*$K32,1))) -> 1 | T32: =IF(M32<0.8*$K32,0,IF(M32<=0.9*$K32,0.5,IF(M32>0.9*$K32,1))) -> 1 | U32: =IF(N32<0.8*$K32,0,IF(N32<=0.9*$K32,0.5,IF(N32>0.9*$K32,1))) -> 1 | V32: =IF(O32<0.8*$K32,0,IF(O32<=0.9*$K32,0.5,IF(O32>0.9*$K32,1))) -> 1 | W32: =IF(P32<0.8*$K32,0,IF(P32<=0.9*$K32,0.5,IF(P32>0.9*$K32,1))) -> 1 | X32: =IF(Q32<0.8*$K32,0,IF(Q32<=0.9*$K32,0.5,IF(Q32>0.9*$K32,1))) -> 0
A33: 29 | B33: GROSS CALORIFIC VALUE | C33: kCal/kg | D33: 6300 | E33: 5800
A34: 30 | B34: BOTTOM ASH LOI | C34: % | D34: 3.4 | E34: 3.5
A35: 31 | B35: FLY ASH LOI | C35: % | D35: 3.4 | E35: 3.5
B37: MILL AVAILABILITY STATUS
A38: 32 | B38: MILL-A STATUS | C38: - | D38: AVAILABLE
A39: 33 | B39: MILL-B STATUS | C39: - | D39: AVAILABLE
A40: 34 | B40: MILL-C STATUS | C40: - | D40: AVAILABLE
A41: 35 | B41: MILL-D STATUS | C41: - | D41: AVAILABLE
...

Sheet AHI Decision Tree
V11: High
D12: Yes
B15: No | E15: Yes | Z15: Yes | AA15: No | AC15: No | AI15: Yes | AL15: No
P17: yes | U17: No | AP17: yes | AT17: No
E22: Yes | G22: No
AG23: yes
AJ24: No
Q25: yes
N26: No
G29: Yes | I29: No
D34: Low
Q35: yes | T35: No
V44: No
S45: yes
Z51: Yes
S52: yes
Q53: No | X53: No

Sheet Mill Merit Order
A1: 1 | B1: BASIC CRITERIA CHECK
B2: NUMBER OF FD FANS IN SERVICE | C2: Nos. | D2: ='INPUT SHEET'!E3=2 -> TRUE
B3: NUMBER OF ID FANS IN SERVICE | C3: Nos. | D3: ='INPUT SHEET'!E4=2 -> TRUE
B4: NUMBER OF PA FANS IN SERVICE | C4: Nos. | D4: ='INPUT SHEET'!E5=2 -> TRUE
B5: NUMBER OF APHs IN SERVICE | C5: Nos. | D5: ='INPUT SHEET'!E6=2 -> TRUE
B6: NUMBER OF SEAL AIR FANS IN SERVICE | C6: Nos. | D6: ='INPUT SHEET'!E7=1 -> TRUE
B7: MILL UNDER MAINTENANCE | C7: - | D7: =IF(COUNTIF(D19:D24,"Not Available")<2,TRUE,FALSE) -> TRUE
B8: LOAD > 60% OF DESIGN | C8: MW | D8: ='INPUT SHEET'!E8>60% -> TRUE
B9: MAIN STEAM FLOW > 60% OF DESIGN | C9: TPH | D9: ='INPUT SHEET'!E9>60% -> TRUE
B10: TOTAL AIR FLOW > 60% OF DESIGN | C10: TPH | D10: ='INPUT SHEET'!E10>60% -> TRUE
B11: TOTAL SECONDARY AIR FLOW > 60% OF DESIGN | C11: TPH | D11: ='INPUT SHEET'!E11>60% -> TRUE
B12: TOTAL COAL FLOW > 60% OF DESIGN | C12: TPH | D12: ='INPUT SHEET'!E12>60% -> TRUE
B14: LOGIC | C14: =IF(COUNTIF(D2:D12,"FALSE")>0,"STOP","PROCEED FOR MILL SCHEDULING") -> PROCEED FOR MILL SCHEDULING
A16: 2 | B16: MILL AVAILABILITY STATUS
B18: DESCRIPTION | C18: UoM | D18: AVAILABILITY | E18: STATUS | F18: ADJ_MILL
B19: MILL-A STATUS | C19: - | D19: ='INPUT SHEET'!D38 -> AVAILABLE | E19: =IF(AND(D19="AVAILABLE",'INPUT SHEET'!L$3>5),"RUNNING","STOP") -> RUNNING | F19: =IF(E20="RUNNING",1,0) -> 1
B20: MILL-B STATUS | C20: - | D20: ='INPUT SHEET'!D39 -> AVAILABLE | E20: =IF(AND(D20="AVAILABLE",'INPUT SHEET'!M$3>5),"RUNNING","STOP") -> RUNNING | F20: =IF(AND(E19="Running",E21="Running"),1,IF(OR(E19="Running",E21="Running"),0.5,0)) -> 1
B21: MILL-C STATUS | C21: - | D21: ='INPUT SHEET'!D40 -> AVAILABLE | E21: =IF(AND(D21="AVAILABLE",'INPUT SHEET'!N$3>5),"RUNNING","STOP") -> RUNNING | F21: =IF(AND(E20="Running",E22="Running"),1,IF(OR(E20="Running",E22="Running"),0.5,0)) -> 1
B22: MILL-D STATUS | C22: - | D22: ='INPUT SHEET'!D41 -> AVAILABLE | E22: =IF(AND(D22="AVAILABLE",'INPUT SHEET'!O$3>5),"RUNNING","STOP") -> RUNNING | F22: =IF(AND(E23="Running",E21="Running"),1,IF(OR(E23="Running",E21="Running"),0.5,0)) -> 1
B23: MILL-E STATUS | C23: - | D23: ='INPUT SHEET'!D42 -> AVAILABLE | E23: =IF(AND(D23="AVAILABLE",'INPUT SHEET'!P$3>5),"RUNNING","STOP") -> RUNNING | F23: =IF(AND(E22="Running",E24="Running"),1,IF(OR(E22="Running",E24="Running"),0.5,0)) -> 0.5
B24: MILL-F STATUS | C24: - | D24: ='INPUT SHEET'!D43 -> AVAILABLE | E24: =IF(AND(D24="AVAILABLE",'INPUT SHEET'!Q$3>5),"RUNNING","STOP") -> STOP | F24: =IF(E23="RUNNING",1,0) -> 1
A26: 3 | B26: ESTIMATION OF MILL HEALTH INDEX
B27: DESCRIPTION | C27: MILL-A | G27: MILL-B | K27: MILL-C | O27: MILL-D | S27: MILL-E | W27: MILL-F
C28: INDIVIDUAL PARAMETERS SCORE | D28: WEIGHTAGE | E28: NORMALISED WEIGHT | F28: HEALTH INDEX | G28: INDIVIDUAL PARAMETERS SCORE | H28: WEIGHTAGE | I28: NORMALISED SCORE | J28: HEALTH INDEX | K28: INDIVIDUAL PARAMETERS SCORE | L28: WEIGHTAGE | M28: NORMALISED SCORE | N28: HEALTH INDEX | O28: INDIVIDUAL PARAMETERS SCORE | P28: WEIGHTAGE | Q28: NORMALISED SCORE | R28: HEALTH INDEX | S28: INDIVIDUAL PARAMETERS SCORE | T28: WEIGHTAGE | U28: NORMALISED SCORE | V28: HEALTH INDEX | W28: INDIVIDUAL PARAMETERS SCORE | X28: WEIGHTAGE | Y28: NORMALISED SCORE | Z28: HEALTH INDEX
B29: ELECTRICAL PARAMETERS | E29: 0.3
B30: INSULATION RESISTANCE | C30: ='INPUT SHEET'!S5 -> 1 | D30: 0.1 | E30: =D30*$E$29 -> 0.03 | F30: =E30*C30 -> 0.03 | G30: ='INPUT SHEET'!T5 -> 1 | H30: 0.1 | I30: =H30*$E$29 -> 0.03 | J30: =I30*G30 -> 0.03 | K30: ='INPUT SHEET'!U5 -> 1 | L30: 0.1 | M30: =L30*$E$29 -> 0.03 | N30: =M30*K30 -> 0.03 | O30: ='INPUT SHEET'!V5 -> 1 | P30: 0.1 | Q30: =P30*$E$29 -> 0.03 | R30: =Q30*O30 -> 0.03 | S30: ='INPUT SHEET'!W5 -> 1 | T30: 0.1 | U30: =T30*$E$29 -> 0.03 | V30: =U30*S30 -> 0.03 | W30: ='INPUT SHEET'!X5 -> 1 | X30: 0.1 | Y30: =X30*$E$29 -> 0.03 | Z30: =Y30*W30 -> 0.03
B31: MOTOR WINDING TEMPERATURE | C31: ='INPUT SHEET'!S6 -> 0.5 | D31: 0.1 | E31: =D31*$E$29 -> 0.03 | F31: =E31*C31 -> 0.015 | G31: ='INPUT SHEET'!T6 -> 0.5 | H31: 0.1 | I31: =H31*$E$29 -> 0.03 | J31: =I31*G31 -> 0.015 | K31: ='INPUT SHEET'!U6 -> 0.5 | L31: 0.1 | M31: =L31*$E$29 -> 0.03 | N31: =M31*K31 -> 0.015 | O31: ='INPUT SHEET'!V6 -> 0.5 | P31: 0.1 | Q31: =P31*$E$29 -> 0.03 | R31: =Q31*O31 -> 0.015 | S31: ='INPUT SHEET'!W6 -> 0.5 | T31: 0.1 | U31: =T31*$E$29 -> 0.03 | V31: =U31*S31 -> 0.015 | W31: ='INPUT SHEET'!X6 -> 0.5 | X31: 0.1 | Y31: =X31*$E$29 -> 0.03 | Z31: =Y31*W31 -> 0.015
B32: POLARISATION INDEX | C32: ='INPUT SHEET'!S7 -> 1 | D32: 0.1 | E32: =D32*$E$29 -> 0.03 | F32: =E32*C32 -> 0.03 | G32: ='INPUT SHEET'!T7 -> 1 | H32: 0.1 | I32: =H32*$E$29 -> 0.03 | J32: =I32*G32 -> 0.03 | K32: ='INPUT SHEET'!U7 -> 1 | L32: 0.1 | M32: =L32*$E$29 -> 0.03 | N32: =M32*K32 -> 0.03 | O32: ='INPUT SHEET'!V7 -> 1 | P32: 0.1 | Q32: =P32*$E$29 -> 0.03 | R32: =Q32*O32 -> 0.03 | S32: ='INPUT SHEET'!W7 -> 1 | T32: 0.1 | U32: =T32*$E$29 -> 0.03 | V32: =U32*S32 -> 0.03 | W32: ='INPUT SHEET'!X7 -> 1 | X32: 0.1 | Y32: =X32*$E$29 -> 0.03 | Z32: =Y32*W32 -> 0.03
B33: TEN DELTA | C33: ='INPUT SHEET'!S8 -> 1 | D33: 0.1 | E33: =D33*$E$29 -> 0.03 | F33: =E33*C33 -> 0.03 | G33: ='INPUT SHEET'!T8 -> 1 | H33: 0.1 | I33: =H33*$E$29 -> 0.03 | J33: =I33*G33 -> 0.03 | K33: ='INPUT SHEET'!U8 -> 1 | L33: 0.1 | M33: =L33*$E$29 -> 0.03 | N33: =M33*K33 -> 0.03 | O33: ='INPUT SHEET'!V8 -> 1 | P33: 0.1 | Q33: =P33*$E$29 -> 0.03 | R33: =Q33*O33 -> 0.03 | S33: ='INPUT SHEET'!W8 -> 1 | T33: 0.1 | U33: =T33*$E$29 -> 0.03 | V33: =U33*S33 -> 0.03 | W33: ='INPUT SHEET'!X8 -> 1 | X33: 0.1 | Y33: =X33*$E$29 -> 0.03 | Z33: =Y33*W33 -> 0.03
B34: MOTOR BEARING VIBRATION | C34: ='INPUT SHEET'!S9 -> 1 | D34: 0.2 | E34: =D34*$E$29 -> 0.06 | F34: =E34*C34 -> 0.06 | G34: ='INPUT SHEET'!T9 -> 1 | H34: 0.2 | I34: =H34*$E$29 -> 0.06 | J34: =I34*G34 -> 0.06 | K34: ='INPUT SHEET'!U9 -> 0.5 | L34: 0.2 | M34: =L34*$E$29 -> 0.06 | N34: =M34*K34 -> 0.03 | O34: ='INPUT SHEET'!V9 -> 1 | P34: 0.2 | Q34: =P34*$E$29 -> 0.06 | R34: =Q34*O34 -> 0.06 | S34: ='INPUT SHEET'!W9 -> 1 | T34: 0.2 | U34: =T34*$E$29 -> 0.06 | V34: =U34*S34 -> 0.06 | W34: ='INPUT SHEET'!X9 -> 1 | X34: 0.2 | Y34: =X34*$E$29 -> 0.06 | Z34: =Y34*W34 -> 0.06
B35: MOTOR BEARING TEMPERATURE | C35: ='INPUT SHEET'!S10 -> 0 | D35: 0.2 | E35: =D35*$E$29 -> 0.06 | F35: =E35*C35 -> 0 | G35: ='INPUT SHEET'!T10 -> 0.5 | H35: 0.2 | I35: =H35*$E$29 -> 0.06 | J35: =I35*G35 -> 0.03 | K35: ='INPUT SHEET'!U10 -> 1 | L35: 0.2 | M35: =L35*$E$29 -> 0.06 | N35: =M35*K35 -> 0.06 | O35: ='INPUT SHEET'!V10 -> 0.5 | P35: 0.2 | Q35: =P35*$E$29 -> 0.06 | R35: =Q35*O35 -> 0.03 | S35: ='INPUT SHEET'!W10 -> 0.5 | T35: 0.2 | U35: =T35*$E$29 -> 0.06 | V35: =U35*S35 -> 0.03 | W35: ='INPUT SHEET'!X10 -> 0.5 | X35: 0.2 | Y35: =X35*$E$29 -> 0.06 | Z35: =Y35*W35 -> 0.03
B36: POWER CONSUMPTION | C36: ='INPUT SHEET'!S11 -> 1 | D36: 0.2 | E36: =D36*$E$29 -> 0.06 | F36: =E36*C36 -> 0.06 | G36: ='INPUT SHEET'!T11 -> 1 | H36: 0.2 | I36: =H36*$E$29 -> 0.06 | J36: =I36*G36 -> 0.06 | K36: ='INPUT SHEET'!U11 -> 1 | L36: 0.2 | M36: =L36*$E$29 -> 0.06 | N36: =M36*K36 -> 0.06 | O36: ='INPUT SHEET'!V11 -> 1 | P36: 0.2 | Q36: =P36*$E$29 -> 0.06 | R36: =Q36*O36 -> 0.06 | S36: ='INPUT SHEET'!W11 -> 0.5 | T36: 0.2 | U36: =T36*$E$29 -> 0.06 | V36: =U36*S36 -> 0.03 | W36: ='INPUT SHEET'!X11 -> 1 | X36: 0.2 | Y36: =X36*$E$29 -> 0.06 | Z36: =Y36*W36 -> 0.06
B37: ELECTRICAL CATEGORY SCORE | F37: =SUM(F30:F36) -> 0.225 | J37: =SUM(J30:J36) -> 0.255 | N37: =SUM(N30:N36) -> 0.255 | R37: =SUM(R30:R36) -> 0.255 | V37: =SUM(V30:V36) -> 0.225 | Z37: =SUM(Z30:Z36) -> 0.255
B38: MECHANICAL PARAMETERS | E38: 0.2
B39: MILL BEARING VIBRATION | C39: ='INPUT SHEET'!S13 -> 0.5 | D39: 0.3 | E39: =D39*$E$38 -> 0.06 | F39: =E39*C39 -> 0.03 | G39: ='INPUT SHEET'!T13 -> 1 | H39: 0.3 | I39: =H39*$E$38 -> 0.06 | J39: =I39*G39 -> 0.06 | K39: ='INPUT SHEET'!U13 -> 1 | L39: 0.3 | M39: =L39*$E$38 -> 0.06 | N39: =M39*K39 -> 0.06 | O39: ='INPUT SHEET'!V13 -> 1 | P39: 0.3 | Q39: =P39*$E$38 -> 0.06 | R39: =Q39*O39 -> 0.06 | S39: ='INPUT SHEET'!W13 -> 1 | T39: 0.3 | U39: =T39*$E$38 -> 0.06 | V39: =U39*S39 -> 0.06 | W39: ='INPUT SHEET'!X13 -> 1 | X39: 0.3 | Y39: =X39*$E$38 -> 0.06 | Z39: =Y39*W39 -> 0.06
B40: MILL BEARING TEMPERATURE | C40: ='INPUT SHEET'!S14 -> 1 | D40: 0.3 | E40: =D40*$E$38 -> 0.06 | F40: =E40*C40 -> 0.06 | G40: ='INPUT SHEET'!T14 -> 0.5 | H40: 0.3 | I40: =H40*$E$38 -> 0.06 | J40: =I40*G40 -> 0.03 | K40: ='INPUT SHEET'!U14 -> 0.5 | L40: 0.3 | M40: =L40*$E$38 -> 0.06 | N40: =M40*K40 -> 0.03 | O40: ='INPUT SHEET'!V14 -> 0.5 | P40: 0.3 | Q40: =P40*$E$38 -> 0.06 | R40: =Q40*O40 -> 0.03 | S40: ='INPUT SHEET'!W14 -> 0.5 | T40: 0.3 | U40: =T40*$E$38 -> 0.06 | V40: =U40*S40 -> 0.03 | W40: ='INPUT SHEET'!X14 -> 0.5 | X40: 0.3 | Y40: =X40*$E$38 -> 0.06 | Z40: =Y40*W40 -> 0.03
B41: MILL/FEEDER ABNORMAL TRIP IN LAST QUARTER | C41: ='INPUT SHEET'!S15 -> 1 | D41: 0.2 | E41: =D41*$E$38 -> 0.04 | F41: =E41*C41 -> 0.04 | G41: ='INPUT SHEET'!T15 -> 1 | H41: 0.2 | I41: =H41*$E$38 -> 0.04 | J41: =I41*G41 -> 0.04 | K41: ='INPUT SHEET'!U15 -> 1 | L41: 0.2 | M41: =L41*$E$38 -> 0.04 | N41: =M41*K41 -> 0.04 | O41: ='INPUT SHEET'!V15 -> 1 | P41: 0.2 | Q41: =P41*$E$38 -> 0.04 | R41: =Q41*O41 -> 0.04 | S41: ='INPUT SHEET'!W15 -> 1 | T41: 0.2 | U41: =T41*$E$38 -> 0.04 | V41: =U41*S41 -> 0.04 | W41: ='INPUT SHEET'!X15 -> 1 | X41: 0.2 | Y41: =X41*$E$38 -> 0.04 | Z41: =Y41*W41 -> 0.04
B42: RUNNING HOURS SINCE LAST MAINTENANCE | C42: ='INPUT SHEET'!S16 -> 0 | D42: 0.2 | E42: =D42*$E$38 -> 0.04 | F42: =E42*C42 -> 0 | G42: ='INPUT SHEET'!T16 -> 1 | H42: 0.2 | I42: =H42*$E$38 -> 0.04 | J42: =I42*G42 -> 0.04 | K42: ='INPUT SHEET'!U16 -> 1 | L42: 0.2 | M42: =L42*$E$38 -> 0.04 | N42: =M42*K42 -> 0.04 | O42: ='INPUT SHEET'!V16 -> 1 | P42: 0.2 | Q42: =P42*$E$38 -> 0.04 | R42: =Q42*O42 -> 0.04 | S42: ='INPUT SHEET'!W16 -> 1 | T42: 0.2 | U42: =T42*$E$38 -> 0.04 | V42: =U42*S42 -> 0.04 | W42: ='INPUT SHEET'!X16 -> 1 | X42: 0.2 | Y42: =X42*$E$38 -> 0.04 | Z42: =Y42*W42 -> 0.04
B43: MECHANICAL CATEGORY SCORE | F43: =SUM(F39:F42) -> 0.13 | J43: =SUM(J39:J42) -> 0.17 | N43: =SUM(N39:N42) -> 0.17 | R43: =SUM(R39:R42) -> 0.17 | V43: =SUM(V39:V42) -> 0.17 | Z43: =SUM(Z39:Z42) -> 0.17
B44: OPERATIONAL PARAMETERS | E44: 0.5
...
